## 异常
- 必须处理的：不处理无法编译
  - 自己处理：try...catch...finally
  - 让别人处理:throws（在方法的声明处添加）
- 可以不处理：一旦发生该异常，程序退出
  - RuntimeException(运行异常)
  - Error(Java虚拟机本身的错误)

异常类

例1：设计一个除法运算器，除数和被除数从命令行输入

```java

public class Helloworld{
	public static void main(String args[]){
		int m = args[0];
		int n = args[1];

		r = div(m, n);
		System.out.println(m + "/" + n + "=" + r);
	}

	public int div(int m, int n){
		int r = m / n;
		return r;
	}
}

```
> 由于args[0]、args[1]都是String类型，自然不能直接赋值给int类型，因此无法编译通过。Integer类中的parseInt方法用于将字符串变成整数，查看方法：打开Java API手册->搜索->输入`integer`->直接搜索`parseInt`->发现时类方法，可以直接调用。请见例2

例2

```java

public class Helloworld{
	public static void main(String args[]){
		int m = Integer.parseInt(args[0]);
		int n = Integer.parseInt(args[1]);

		int r = div(m, n);
		System.out.println(m + "/" + n + "=" + r);
	}

	public static int div(int m, int n){
		int r = m / n;
		return r;
	}
}

```
> 运行程序`java Helloworld 6 2`,发现程序输出正确结果。运行程序`java Helloworld 6 0`,程序出现异常。我们在`int r = div(m, n);`的前后添加打印调试语句，见例3

例3

```java

public class Helloworld{
	public static void main(String args[]){
		int m = Integer.parseInt(args[0]);
		int n = Integer.parseInt(args[1]);
		
		System.out.println("Begin of div");
		int r = div(m, n);
		System.out.println("End of div");

		System.out.println(m + "/" + n + "=" + r);
	}

	public static int div(int m, int n){
		int r = m / n;
		return r;
	}
}

```
> 当执行div方法时，由于除数是0，发生了一个RuntimeError。由于我们没有对这个异常做任何处理 ，因此程序退出。下面采用自己处理异常的方式进行处理。

```java

public class Helloworld{
	public static void main(String args[]){
		int m = Integer.parseInt(args[0]);
		int n = Integer.parseInt(args[1]);

		System.out.println("Begin of div");
		int r = div(m, n);
		System.out.println("End of div");
		
		System.out.println(m + "/" + n + "=" + r);
	}

	public static int div(int m, int n){
		int r = 0;
		try{
			r = m / n;
		}catch(ArithmeticException e){
			System.out.println(e);
		}
		 
		return r;
	}
}
```
> 程序试着执行r = m / n;如果发现有算数异常ArithmeticException，则会被正在等待的catch语句捕捉到，这样程序就不会崩溃退出。怎么知道要捕捉ArithmeticException异常呢？可从例3的cmd错误输出中知道。

```java

public class Helloworld{
	public static void main(String args[]){
		int m = Integer.parseInt(args[0]);
		int n = Integer.parseInt(args[1]);

		System.out.println("Begin of div");
		int r = div(m, n);
		System.out.println("End of div");
		
		System.out.println(m + "/" + n + "=" + r);
	}

	public static int div(int m, int n){
		int r = 0;
		try{
			r = m / n;
		}catch(ArithmeticException e){
			System.out.println(e);
		}finally{
			System.out.println("This is finally of div");
		}
		 
		return r;
	}
}

```
> 最后添加`finally`语句，构成`try...catch...finally`。finally语句最后都会被执行。

下面的例子是自己不处理异常，采用扔给别人处理的方式来处理：
```java

public class Helloworld{
	public static void main(String args[]){
		int m = Integer.parseInt(args[0]);
		int n = Integer.parseInt(args[1]);

		System.out.println("Begin of div");
		int r = div(m, n);
		System.out.println("End of div");
		
		System.out.println(m + "/" + n + "=" + r);
	}

	public static int div(int m, int n)throws ArithmeticException{
		int r = 0;
		r = m / n;
		 
		return r;
	}
}

```
> div自己不捕捉处理异常，而是将ArithmeticException异常扔出给调用者main函数，但是main函数自己却没做任何处理。因此程序还是会崩溃。办法：在main函数中做异常处理。

```java
public class Helloworld{
	public static void main(String args[]){
		int m = Integer.parseInt(args[0]);
		int n = Integer.parseInt(args[1]);
		int r = 0;
		System.out.println("Begin of div");
		try{
			r = div(m, n);
		}catch(ArithmeticException e){
			System.out.println(e);	
		}finally{
			System.out.println("This is finally of div");
		}
		System.out.println("End of div");
		
		System.out.println(m + "/" + n + "=" + r);
	}

	public static int div(int m, int n)throws ArithmeticException{  /* 扔出异常的声明 */
		int r = 0;
		r = m / n;
		 
		return r;
	}
}

```
> 现在main函数中对ArithmeticException异常做了捕获处理。

```java
public class Helloworld{
	public static void main(String args[]){
		int m = Integer.parseInt(args[0]);
		int n = Integer.parseInt(args[1]);
		int r = 0;
		System.out.println("Begin of div");
		try{
			r = div(m, n);
		}catch(ArithmeticException e){
			System.out.println(e);	
		}finally{
			System.out.println("This is finally of div");
		}
		System.out.println("End of div");
		
		System.out.println(m + "/" + n + "=" + r);
	}

	public static int div(int m, int n)throws ArithmeticException{
		int r = 0;
		try{
			r = m / n;
		}catch(ArithmeticException e){
			System.out.println("div:" + e);	
		}
		return r;
	}
}

```
> div方法自己做异常的捕获，同时也把异常扔给主调函数main,并在其中做了异常捕获。这种情况下，异常在div中被捕获后，就被处理完毕，它不会再次在main中被捕获。那么如何让调用者main和被调者div来协同处理这个异常呢？注意：当传入参数n为0时，系统在执行try中的`r = m / n`时会抛出一个异常，然后这个异常被div自己的catch语句捕获。怎么让main函数再次收到这个异常呢?答案：在catch中再次抛出这个异常！

```java
public class Helloworld{
	public static void main(String args[]){
		int m = Integer.parseInt(args[0]);
		int n = Integer.parseInt(args[1]);
		int r = 0;
		System.out.println("Begin of div");
		try{
			r = div(m, n);
		}catch(ArithmeticException e){
			System.out.println("main" + e);	
		}finally{
			System.out.println("This is finally of div");
		}
		System.out.println("End of div");
		
		System.out.println(m + "/" + n + "=" + r);
	}

	public static int div(int m, int n)throws ArithmeticException{
		int r = 0;
		try{
			r = m / n;
		}catch(ArithmeticException e){
			System.out.println("div:" + e);	
			throw e;  //人为抛出一个异常
		}
		return r;
	}
}

```
> 执行程序时，如果输入`java Helloworld 6 a`时，会发现NumberFormatException,也就是数字格式异常，因为Integer.parseInt默认要求输入的是数字字符，否则无法转化。如果输入a,b，....就无法转化成数字了，出现异常，怎么办呢？捕获该异常！

```java
public class Helloworld{
	public static void main(String args[]){
		int m = 0;
		int n = 0;
		int r = 0;
		System.out.println("Begin of div");
		try{
			m = Integer.parseInt(args[0]);
			n = Integer.parseInt(args[1]);
			r = div(m, n);
		}catch(ArithmeticException e){
			System.out.println("main:" + e);	
		}catch(NumberFormatException e){
			System.out.println("main:" + e);
			
		}
		System.out.println("End of div");
		
		System.out.println(m + "/" + n + "=" + r);
	}

	public static int div(int m, int n)throws ArithmeticException{
		int r = 0;
		try{
			r = m / n;
		}catch(ArithmeticException e){
			System.out.println("div:" + e);	
			throw e;
		}
		return r;
	}
}

```
> 如果输入`java Helloworld 6 `呢？发现程序又会出现其他异常（数组异常），因此，对于不同的不可预期输入，程序会发生各种异常。那怎么捕获各种各样的异常呢？直接捕获这些ArithmeticException、NumberFormatException异常的父类RuntimeException！

```java
public class Helloworld{
	public static void main(String args[]){
		int m = 0;
		int n = 0;
		int r = 0;
		System.out.println("Begin of div");
		try{
			m = Integer.parseInt(args[0]);
			n = Integer.parseInt(args[1]);
			r = div(m, n);
		}catch(ArithmeticException e){
			System.out.println("main:" + e);	
		}catch(NumberFormatException e){
			System.out.println("main:" + e);	
		}
		catch(RuntimeException e){
			System.out.println("main:" + e);	
		}
		System.out.println("End of div");
		
		System.out.println(m + "/" + n + "=" + r);
	}

	public static int div(int m, int n)throws ArithmeticException{
		int r = 0;
		try{
			r = m / n;
		}catch(ArithmeticException e){
			System.out.println("div:" + e);	
			throw e;
		}
		return r;
	}
}

```
> 注意，必须将RuntimeException的异常捕获放在最后，如果放在最前面，则编译都无法通过。原则：先捕获子类异常，如果有漏网之鱼，再父类捕获。

```java
public class Helloworld{
	public static void main(String args[]){
		int m = 0;
		int n = 0;
		int r = 0;
		System.out.println("Begin of div");
		try{
			m = Integer.parseInt(args[0]);
			n = Integer.parseInt(args[1]);
			r = div(m, n);
		}
		catch(ArithmeticException e){
			System.out.println("main:" + e);	
		}catch(NumberFormatException e){
			System.out.println("main:" + e);	
		}catch(RuntimeException e){
			System.out.println("main:" + e);	
		}
		
		System.out.println("End of div");
		
		System.out.println(m + "/" + n + "=" + r);
	}

	public static int div(int m, int n)throws ArithmeticException{
		int r = 0;
		try{
			r = m / n;
		}catch(ArithmeticException e){
			System.out.println("div:" + e);	
			throw e;
		}finally{
			System.out.println("this is finally of div" );
			return r;
		}
		//return r;
	}
}

```
> 如果我在div中添加返回语句`return r`呢，会出现什么结果呢？这时候，因为该语句在finally中，因此该语句肯定会被执行到，同时最后的`return r`语句可以删除掉。系统在执行catch中的`throw e`语句之前，会先执行fianlly语句，而由于finally语句中有返回语句`return r`,因此再未执行`throw e`语句之时，就会提前退出，所以就不会扔出这个异常，main函数当然捕捉不到。如果finally语句中没有返回语句`return r`，则会继续执行`throw e`语句，执行`throw e`语句的结果就会退出当前div函数。也就是说：try或catch块中有return或throw语句，会先执行finally块，再返回来执行return或throw语句，所以，如果finally块中有return语句的话，那么方法会先返回，则try或catch 块中剩下的return或throw语句不会执行

> 不可查的异常(unchecked exceptions):RuntimeException及其子类,这是在运行时产生的异常，我们事先不可预知，程序中可以捕获处理它，也可以不处理。因此对于“不可查异常”, 系统也会抛出它，写不写throws效果一样。例如，可将上面的div函数定义处的`throws ArithmeticException`去掉。
> 可查的异常(checked exceptions)：除了RuntimeException及其子类之外的异常。对于可查异常必须捕捉、或者声明抛出，否则连编译都过不了。见下例


```java
public class Helloworld{
	public static void main(String args[]){
		int m = 0;
		int n = 0;
		int r = 0;
		System.out.println("Begin of div");
		try{
			m = Integer.parseInt(args[0]);
			n = Integer.parseInt(args[1]);
			r = div(m, n);
		}
		catch(ArithmeticException e){
			System.out.println("main:" + e);	
		}catch(NumberFormatException e){
			System.out.println("main:" + e);	
		}catch(RuntimeException e){
			System.out.println("main:" + e);	
		}
		
		System.out.println("End of div");
		
		System.out.println(m + "/" + n + "=" + r);
	}

	public static int div(int m, int n)throws ArithmeticException{
		int r = 0;
		try{
			r = m / n;
		}catch(ArithmeticException e){
			System.out.println("div:" + e);	
			throw new Exception(“My Error”);  /* 手工创建一个异常 */
		}finally{
			System.out.println("this is finally of div" );
			
		}
		return r;
	}
}

```
> Exception类中的RuntimeException类及其子类是不可查异常，那么Exception类中必然有可查异常，我们可以新建一个Exception类的实例化对象。但是程序无法编译通过。因为Exception类中的可查异常，必须在程序中处理，而我们在这里没有对它进行处理。因此，可以自己处理或扔给别人。下面将它扔给别人处理。

```java
public class Helloworld{
	public static void main(String args[]){
		int m = 0;
		int n = 0;
		int r = 0;
		System.out.println("Begin of div");
		try{
			m = Integer.parseInt(args[0]);
			n = Integer.parseInt(args[1]);
			r = div(m, n);
		}
		catch(ArithmeticException e){
			System.out.println("main:" + e);	
		}catch(NumberFormatException e){
			System.out.println("main:" + e);	
		}catch(RuntimeException e){
			System.out.println("main:" + e);	
		}catch(Exception e){                  //在这里处理不可查异常
			System.out.println("main:" + e);	
		}
		
		System.out.println("End of div");
		
		System.out.println(m + "/" + n + "=" + r);
	}

	public static int div(int m, int n)throws Exception{  //扔出这个 Exception（不可查异常）
		int r = 0;
		try{
			r = m / n;
		}catch(ArithmeticException e){
			System.out.println("div:" + e);	
			throw new Exception();
		}finally{
			System.out.println("this is finally of div" );
			
		}
		return r;
	}
}

```
> 注意：对于不可查异常，既然必须要处理，而自己如果不处理的话，就扔给别人处理：包含“扔”+“处理”。所以：1.必须声明要抛出这个异常错误`throws Exception`。2.必须在主调函数main中catch这个异常。如果采用自己处理，则如下：

```java

public class Helloworld{
	public static void main(String args[]){
		int m = 0;
		int n = 0;
		int r = 0;
		System.out.println("Begin of div");
		try{
			m = Integer.parseInt(args[0]);
			n = Integer.parseInt(args[1]);
			r = div(m, n);
		}
		catch(ArithmeticException e){
			System.out.println("main:" + e);	
		}catch(NumberFormatException e){
			System.out.println("main:" + e);	
		}catch(RuntimeException e){
			System.out.println("main:" + e);	
		}catch(Exception e){
			System.out.println("main:" + e);	
		}
		
		System.out.println("End of div");
		
		System.out.println(m + "/" + n + "=" + r);
	}

	public static int div(int m, int n){
		int r = 0;
		try{
			r = m / n;
		}catch(ArithmeticException e){
			System.out.println("div:" + e);
			
			try{
				throw new Exception("My Error");
			}catch(Exception e2){
			System.out.println("div:" + e2);
			}
		}finally{
			System.out.println("this is finally of div" );
			
		}
		return r;
	}
}

```
[更多内容，请见这里][http://blog.csdn.net/hguisu/article/details/6155636]
