## 异常
- 必须处理的：不处理无法编译
  - 自己处理：try...catch...finally
  - 让别人处理:throws
- 可以不处理：一旦发生该异常，程序退出
  - RuntimeException(运行异常)
  - Error(Java虚拟机本身的错误)

异常类

例1：设计一个除法运算器，除数和被除数从命令行输入

```java

public class Helloworld{
	public static void main(String args[]){
		int m = args[0];
		int n = args[1];

		r = div(m, n);
		System.out.println(m + "/" + n + "=" + r);
	}

	public int div(int m, int n){
		int r = m / n;
		return r;
	}
}

```
> 由于args[0]、args[1]都是String类型，自然不能直接赋值给int类型，因此无法编译通过。Integer类中的parseInt方法用于将字符串变成整数，查看方法：打开Java API手册->搜索->输入`integer`->直接搜索`parseInt`->发现时类方法，可以直接调用。请见例2

例2

```java

public class Helloworld{
	public static void main(String args[]){
		int m = Integer.parseInt(args[0]);
		int n = Integer.parseInt(args[1]);

		int r = div(m, n);
		System.out.println(m + "/" + n + "=" + r);
	}

	public static int div(int m, int n){
		int r = m / n;
		return r;
	}
}

```
> 运行程序`java Helloworld 6 2`,发现程序输出正确结果。运行程序`java Helloworld 6 0`,程序出现异常。我们在`int r = div(m, n);`的前后添加打印调试语句，见例3

例3

```java

public class Helloworld{
	public static void main(String args[]){
		int m = Integer.parseInt(args[0]);
		int n = Integer.parseInt(args[1]);
		
		System.out.println("Begin of div");
		int r = div(m, n);
		System.out.println("End of div");

		System.out.println(m + "/" + n + "=" + r);
	}

	public static int div(int m, int n){
		int r = m / n;
		return r;
	}
}

```
> 当执行div方法时，由于除数是0，发生了一个RuntimeError。由于我们没有对这个异常做任何处理 ，因此程序退出。下面采用自己处理异常的方式进行处理。

```java

public class Helloworld{
	public static void main(String args[]){
		int m = Integer.parseInt(args[0]);
		int n = Integer.parseInt(args[1]);

		System.out.println("Begin of div");
		int r = div(m, n);
		System.out.println("End of div");
		
		System.out.println(m + "/" + n + "=" + r);
	}

	public static int div(int m, int n){
		int r = 0;
		try{
			r = m / n;
		}catch(ArithmeticException e){
			System.out.println(e);
		}
		 
		return r;
	}
}
```
> 程序试着执行r = m / n;如果发现有算数异常ArithmeticException，则会被正在等待的catch语句捕捉到，这样程序就不会崩溃退出。怎么知道要捕捉ArithmeticException异常呢？可从例3的cmd错误输出中知道。

```java

public class Helloworld{
	public static void main(String args[]){
		int m = Integer.parseInt(args[0]);
		int n = Integer.parseInt(args[1]);

		System.out.println("Begin of div");
		int r = div(m, n);
		System.out.println("End of div");
		
		System.out.println(m + "/" + n + "=" + r);
	}

	public static int div(int m, int n){
		int r = 0;
		try{
			r = m / n;
		}catch(ArithmeticException e){
			System.out.println(e);
		}finally{
			System.out.println("This is finally of div");
		}
		 
		return r;
	}
}

```
> 最后添加`finally`语句，构成`try...catch...finally`。finally语句最后都会被执行。采用别人处理的方式来处理。

```java

public class Helloworld{
	public static void main(String args[]){
		int m = Integer.parseInt(args[0]);
		int n = Integer.parseInt(args[1]);

		System.out.println("Begin of div");
		int r = div(m, n);
		System.out.println("End of div");
		
		System.out.println(m + "/" + n + "=" + r);
	}

	public static int div(int m, int n)throws ArithmeticException{
		int r = 0;
		r = m / n;
		 
		return r;
	}
}

```
> div自己不捕捉处理异常，而是将ArithmeticException异常扔出给调用者main函数，但是main函数自己却没做任何处理。因此程序还是会崩溃。办法：在main函数中做异常处理。

```java
public class Helloworld{
	public static void main(String args[]){
		int m = Integer.parseInt(args[0]);
		int n = Integer.parseInt(args[1]);
		int r = 0;
		System.out.println("Begin of div");
		try{
			r = div(m, n);
		}catch(ArithmeticException e){
			System.out.println(e);	
		}finally{
			System.out.println("This is finally of div");
		}
		System.out.println("End of div");
		
		System.out.println(m + "/" + n + "=" + r);
	}

	public static int div(int m, int n)throws ArithmeticException{
		int r = 0;
		r = m / n;
		 
		return r;
	}
}

```
